Workbook

Sheet About

Sheet Raw Financial Data
A2: Consolidated Income Statement
A4: (in € millions) | B4: 2020 | C4: 2021 | D4: 2022 | E4: 2023 | F4: 2024 | G4: 2025
A5: CONTINUING OPERATIONS
A6: Revenue | B6: 13100.2 | C6: 17645 | D6: 20351 | E6: 19566 | F6: 16874 | G6: 14675
A7: Cost of sales | B7: -3590.6 | C7: (4,577) | D7: (5,153) | E7: (4,639) | F7: (4,480) | G7: (4,015)
A8: Gross margin | B8: 9509.6 | C8: 13068 | D8: 15198 | E8: 14927 | F8: 12394 | G8: 10660
A9: Personnel expenses | B9: -2070 | C9: (2,444) | D9: (2,830) | E9: (2,982) | F9: (2,954) | G9: (2,777)
A10: Other recurring operating income and expenses | B10: -4304.4 | C10: (5,607) | D10: (6,779) | E10: (7,199) | F10: (7,000) | G10: (6,252)
A11: Recurring operating income | B11: 3135.2 | C11: 5017 | D11: 5589 | E11: 4746 | F11: 2440 | G11: 1631
A12: Other non-recurring operating income and expenses | B12: 163 | C12: (220) | D12: (194) | E12: (103) | F12: (242) | G12: (584)
A13: Operating income | B13: 3298.2 | C13: 4797 | D13: 5395 | E13: 4643 | F13: 2198 | G13: 1047
A14: Financial result | B14: -341.7 | C14: (273) | D14: (260) | E14: (410) | F14: (614) | G14: (594)
A15: Income before tax | B15: 2956.5 | C15: 4524 | D15: 5135 | E15: 4233 | F15: 1584 | G15: 453
A16: Income tax expense | B16: -759.2 | C16: (1,280) | D16: (1,420) | E16: (1,163) | F16: (455) | G16: (354)
A17: Share in earnings (losses) of equity-accounted companies | B17: -7.6 | C17: 1 | D17: 2 | E17: 4 | F17: (10) | G17: (60)
A18: Net income from continuing operations | B18: 2189.7 | C18: 3245 | D18: 3717 | E18: 3074 | F18: 1119 | G18: 39
A19: o/w attributable to the Group | B19: 2160.2 | C19: 3165 | D19: 3613 | E19: 2983 | F19: 1025 | G19: (29)
A20: o/w attributable to minority interests | B20: 29.5 | C20: 80 | D20: 104 | E20: 91 | F20: 94 | G20: 68
A21: DISCONTINUED OPERATIONS
A22: Net income (loss) from discontinued operations | B22: -9.8 | C22: 11 | D22: 1 | E22: – | F22: 108 | G22: 101
A23: o/w attributable to the Group | B23: -9.8 | C23: 11 | D23: 1 | E23: – | F23: 108 | G23: 101
A24: o/w attributable to minority interests | B24: – | C24: – | D24: – | E24: – | F24: – | G24: –
A25: GROUP TOTAL
A26: Net income of consolidated companies | B26: 2179.9 | C26: 3256 | D26: 3718 | E26: 3074 | F26: 1227 | G26: 140
A27: o/w attributable to the Group | B27: 2150.4 | C27: 3176 | D27: 3614 | E27: 2983 | F27: 1133 | G27: 72
A28: o/w attributable to minority interests | B28: 29.5 | C28: 80 | D28: 104 | E28: 91 | F28: 94 | G28: 68
A30: (in € millions) | B30: 2020 | C30: 2021 | D30: 2022 | E30: 2023 | F30: 2024 | G30: 2025
A31: Net income attributable to the Group (€m) | B31: 2150.4 | C31: 3176 | D31: 3614 | E31: 2983 | F31: 1133 | G31: 72
A32: Basic earnings per share (€) | B32: 17.2 | C32: 25.49 | D32: 29.34 | E32: 24.38 | F32: 9.24 | G32: 0.59
A33: Diluted earnings per share (€) | B33: 17.2 | C33: 25.49 | D33: 29.31 | E33: 24.37 | F33: 9.24 | G33: 0.59
A34: Net income from continuing operations attributable to the Group (€m) | B34: 2160.2 | C34: 3165 | D34: 3613 | E34: 2983 | F34: 1025 | G34: -29
A35: Basic EPS from continuing operations | B35: 17.28 | C35: 25.4 | D35: 29.33 | E35: 24.38 | F35: 8.36 | G35: (0.23)
A36: Diluted EPS from continuing operations | B36: 17.28 | C36: 25.4 | D36: 29.3 | E36: 24.37 | F36: 8.36 | G36: (0.23)
A37: Net income from continuing operations (excluding non-recurring items) attributable to the Group (€m) | B37: 1972.2 | C37: 3361 | D37: 3747 | E37: 3061 | F37: 1206 | G37: 532
A38: Basic EPS excluding non-recurring items | B38: 15.78 | C38: 26.98 | D38: 30.42 | E38: 25.02 | F38: 9.84 | G38: 4.34
A39: Diluted EPS excluding non-recurring items | B39: 15.78 | C39: 26.98 | D39: 30.39 | E39: 25.01 | F39: 9.84 | G39: 4.34
A40: Net income from discontinued operations attributable to the Group (€m) | C40: 11 | D40: 1 | E40: – | F40: 108 | G40: 101
A41: Basic EPS from discontinued operations | C41: 0.09 | D41: 0.01 | E41: – | F41: 0.88 | G41: 0.82
A42: Diluted EPS from discontinued operations | C42: 0.09 | D42: 0.01 | E42: – | F42: 0.88 | G42: 0.82
A45: Consolidated Balance Sheet (Dec, 31st)
...

Sheet Common Size Financial Statement
A2: Common Sized Consolidated Income Statement
A4: (% of Revenue) | B4: 2021 | C4: 2022 | D4: 2023 | E4: 2024 | F4: 2025 | G4: AVG.
A5: CONTINUING OPERATIONS
A6: Revenue | B6: =(Financial_Statements[[#This Row],[Column2]]/'Raw Financial Data'!C$6) -> 1 | C6: =(Financial_Statements[[#This Row],[Column3]]/'Raw Financial Data'!D$6) -> 1 | D6: =(Financial_Statements[[#This Row],[Column4]]/'Raw Financial Data'!E$6) -> 1 | E6: =(Financial_Statements[[#This Row],[Column5]]/'Raw Financial Data'!F$6) -> 1 | F6: =(Financial_Statements[[#This Row],[Column6]]/'Raw Financial Data'!G$6) -> 1 | G6: =AVERAGE(B6,C6,D6,E6,F6) -> 1
A7: Cost of sales | B7: =(Financial_Statements[[#This Row],[Column2]]/'Raw Financial Data'!C$6) -> -0.2593936 | C7: =(Financial_Statements[[#This Row],[Column3]]/'Raw Financial Data'!D$6) -> -0.25320623 | D7: =(Financial_Statements[[#This Row],[Column4]]/'Raw Financial Data'!E$6) -> -0.23709496 | E7: =(Financial_Statements[[#This Row],[Column5]]/'Raw Financial Data'!F$6) -> -0.26549721 | F7: =(Financial_Statements[[#This Row],[Column6]]/'Raw Financial Data'!G$6) -> -0.27359455 | G7: =AVERAGE(D7,E7,F7) -> -0.25872891
A8: Gross margin | B8: =(Financial_Statements[[#This Row],[Column2]]/'Raw Financial Data'!C$6) -> 0.7406064 | C8: =(Financial_Statements[[#This Row],[Column3]]/'Raw Financial Data'!D$6) -> 0.74679377 | D8: =(Financial_Statements[[#This Row],[Column4]]/'Raw Financial Data'!E$6) -> 0.76290504 | E8: =(Financial_Statements[[#This Row],[Column5]]/'Raw Financial Data'!F$6) -> 0.73450279 | F8: =(Financial_Statements[[#This Row],[Column6]]/'Raw Financial Data'!G$6) -> 0.72640545 | G8: =AVERAGE(D8,E8,F8) -> 0.74127109
A9: Other personnel expenses | B9: =(Financial_Statements[[#This Row],[Column2]]/'Raw Financial Data'!C$6) -> -0.13850949 | C9: =(Financial_Statements[[#This Row],[Column3]]/'Raw Financial Data'!D$6) -> -0.13905951 | D9: =(Financial_Statements[[#This Row],[Column4]]/'Raw Financial Data'!E$6) -> -0.15240724 | E9: =(Financial_Statements[[#This Row],[Column5]]/'Raw Financial Data'!F$6) -> -0.17506223 | F9: =(Financial_Statements[[#This Row],[Column6]]/'Raw Financial Data'!G$6) -> -0.18923339 | G9: =AVERAGE(D9,E9,F9) -> -0.17223428
A10: Other recurring operating income and expenses | B10: =(Financial_Statements[[#This Row],[Column2]]/'Raw Financial Data'!C$6) -> -0.31776707 | C10: =(Financial_Statements[[#This Row],[Column3]]/'Raw Financial Data'!D$6) -> -0.33310402 | D10: =(Financial_Statements[[#This Row],[Column4]]/'Raw Financial Data'!E$6) -> -0.36793417 | E10: =(Financial_Statements[[#This Row],[Column5]]/'Raw Financial Data'!F$6) -> -0.4148394 | F10: =(Financial_Statements[[#This Row],[Column6]]/'Raw Financial Data'!G$6) -> -0.42603066 | G10: =AVERAGE(D10,E10,F10) -> -0.40293474
A11: Recurring operating income | B11: =(Financial_Statements[[#This Row],[Column2]]/'Raw Financial Data'!C$6) -> 0.28432984 | C11: =(Financial_Statements[[#This Row],[Column3]]/'Raw Financial Data'!D$6) -> 0.27463024 | D11: =(Financial_Statements[[#This Row],[Column4]]/'Raw Financial Data'!E$6) -> 0.24256363 | E11: =(Financial_Statements[[#This Row],[Column5]]/'Raw Financial Data'!F$6) -> 0.14460116 | F11: =(Financial_Statements[[#This Row],[Column6]]/'Raw Financial Data'!G$6) -> 0.1111414 | G11: =AVERAGE(D11,E11,F11) -> 0.16610206
A12: Other non-recurring operating income and expenses | B12: =(Financial_Statements[[#This Row],[Column2]]/'Raw Financial Data'!C$6) -> -0.012468121 | C12: =(Financial_Statements[[#This Row],[Column3]]/'Raw Financial Data'!D$6) -> -0.0095327011 | D12: =(Financial_Statements[[#This Row],[Column4]]/'Raw Financial Data'!E$6) -> -0.0052642339 | E12: =(Financial_Statements[[#This Row],[Column5]]/'Raw Financial Data'!F$6) -> -0.014341591 | F12: =(Financial_Statements[[#This Row],[Column6]]/'Raw Financial Data'!G$6) -> -0.039795571 | G12: =AVERAGE(D12,E12,F12) -> -0.019800465
A13: Operating income | B13: =(Financial_Statements[[#This Row],[Column2]]/'Raw Financial Data'!C$6) -> 0.27186172 | C13: =(Financial_Statements[[#This Row],[Column3]]/'Raw Financial Data'!D$6) -> 0.26509754 | D13: =(Financial_Statements[[#This Row],[Column4]]/'Raw Financial Data'!E$6) -> 0.2372994 | E13: =(Financial_Statements[[#This Row],[Column5]]/'Raw Financial Data'!F$6) -> 0.13025957 | F13: =(Financial_Statements[[#This Row],[Column6]]/'Raw Financial Data'!G$6) -> 0.071345826 | G13: =AVERAGE(D13,E13,F13) -> 0.1463016
A14: Financial result | B14: =(Financial_Statements[[#This Row],[Column2]]/'Raw Financial Data'!C$6) -> -0.015471805 | C14: =(Financial_Statements[[#This Row],[Column3]]/'Raw Financial Data'!D$6) -> -0.012775785 | D14: =(Financial_Statements[[#This Row],[Column4]]/'Raw Financial Data'!E$6) -> -0.020954717 | E14: =(Financial_Statements[[#This Row],[Column5]]/'Raw Financial Data'!F$6) -> -0.036387341 | F14: =(Financial_Statements[[#This Row],[Column6]]/'Raw Financial Data'!G$6) -> -0.040477002 | G14: =AVERAGE(D14,E14,F14) -> -0.032606354
A15: Income before tax | B15: =(Financial_Statements[[#This Row],[Column2]]/'Raw Financial Data'!C$6) -> 0.25638991 | C15: =(Financial_Statements[[#This Row],[Column3]]/'Raw Financial Data'!D$6) -> 0.25232175 | D15: =(Financial_Statements[[#This Row],[Column4]]/'Raw Financial Data'!E$6) -> 0.21634468 | E15: =(Financial_Statements[[#This Row],[Column5]]/'Raw Financial Data'!F$6) -> 0.093872229 | F15: =(Financial_Statements[[#This Row],[Column6]]/'Raw Financial Data'!G$6) -> 0.030868825 | G15: =AVERAGE(D15,E15,F15) -> 0.11369524
A16: Income tax expense | B16: =(Financial_Statements[[#This Row],[Column2]]/'Raw Financial Data'!C$6) -> -0.072541797 | C16: =(Financial_Statements[[#This Row],[Column3]]/'Raw Financial Data'!D$6) -> -0.069775441 | D16: =(Financial_Statements[[#This Row],[Column4]]/'Raw Financial Data'!E$6) -> -0.059439845 | E16: =(Financial_Statements[[#This Row],[Column5]]/'Raw Financial Data'!F$6) -> -0.026964561 | F16: =(Financial_Statements[[#This Row],[Column6]]/'Raw Financial Data'!G$6) -> -0.024122658 | G16: =AVERAGE(D16,E16,F16) -> -0.036842354
A17: Share in earnings (losses) of equity-accounted companies | B17: =(Financial_Statements[[#This Row],[Column2]]/'Raw Financial Data'!C$6) -> 5.6673279e-05 | C17: =(Financial_Statements[[#This Row],[Column3]]/'Raw Financial Data'!D$6) -> 9.8275269e-05 | D17: =(Financial_Statements[[#This Row],[Column4]]/'Raw Financial Data'!E$6) -> 0.00020443627 | E17: =(Financial_Statements[[#This Row],[Column5]]/'Raw Financial Data'!F$6) -> -0.00059262771 | F17: =(Financial_Statements[[#This Row],[Column6]]/'Raw Financial Data'!G$6) -> -0.004088586 | G17: =AVERAGE(D17,E17,F17) -> -0.0014922592
A18: Net income from continuing operations | B18: =(Financial_Statements[[#This Row],[Column2]]/'Raw Financial Data'!C$6) -> 0.18390479 | C18: =(Financial_Statements[[#This Row],[Column3]]/'Raw Financial Data'!D$6) -> 0.18264459 | D18: =(Financial_Statements[[#This Row],[Column4]]/'Raw Financial Data'!E$6) -> 0.15710927 | E18: =(Financial_Statements[[#This Row],[Column5]]/'Raw Financial Data'!F$6) -> 0.066315041 | F18: =(Financial_Statements[[#This Row],[Column6]]/'Raw Financial Data'!G$6) -> 0.0026575809 | G18: =AVERAGE(D18,E18,F18) -> 0.075360631
... A20: o/w attributable to minority interests | B20: =(Financial_Statements[[#This Row],[Column2]]/'Raw Financial Data'!C$6) -> 0.0045338623 | C20: =(Financial_Statements[[#This Row],[Column3]]/'Raw Financial Data'!D$6) -> 0.005110314 | D20: =(Financial_Statements[[#This Row],[Column4]]/'Raw Financial Data'!E$6) -> 0.0046509251 | E20: =(Financial_Statements[[#This Row],[Column5]]/'Raw Financial Data'!F$6) -> 0.0055707005 | F20: =(Financial_Statements[[#This Row],[Column6]]/'Raw Financial Data'!G$6) -> 0.0046337308 | G20: =AVERAGE(D20,E20,F20) -> 0.0049517855
A21: DISCONTINUED OPERATIONS
A22: Net income from discontinued operations | B22: =(Financial_Statements[[#This Row],[Column2]]/'Raw Financial Data'!C$6) -> 0.00062340606 | C22: =(Financial_Statements[[#This Row],[Column3]]/'Raw Financial Data'!D$6) -> 4.9137635e-05 | D22: 0 | E22: =(Financial_Statements[[#This Row],[Column5]]/'Raw Financial Data'!F$6) -> 0.0064003793 | F22: =(Financial_Statements[[#This Row],[Column6]]/'Raw Financial Data'!G$6) -> 0.0068824532 | G22: =AVERAGE(D22,E22,F22) -> 0.0044276108
A23: o/w attributable to the Group | B23: =(Financial_Statements[[#This Row],[Column2]]/'Raw Financial Data'!C$6) -> 0.00062340606 | C23: =(Financial_Statements[[#This Row],[Column3]]/'Raw Financial Data'!D$6) -> 4.9137635e-05 | D23: 0 | E23: =(Financial_Statements[[#This Row],[Column5]]/'Raw Financial Data'!F$6) -> 0.0064003793 | F23: =(Financial_Statements[[#This Row],[Column6]]/'Raw Financial Data'!G$6) -> 0.0068824532 | G23: =AVERAGE(D23,E23,F23) -> 0.0044276108
A24: o/w attributable to minority interests | B24: 0 | C24: 0 | D24: 0 | E24: 0 | F24: 0 | G24: =AVERAGE(D24,E24,F24) -> 0
A25: GROUP TOTAL
A26: Net income of consolidated companies | B26: =(Financial_Statements[[#This Row],[Column2]]/'Raw Financial Data'!C$6) -> 0.18452819 | C26: =(Financial_Statements[[#This Row],[Column3]]/'Raw Financial Data'!D$6) -> 0.18269373 | D26: =(Financial_Statements[[#This Row],[Column4]]/'Raw Financial Data'!E$6) -> 0.15710927 | E26: =(Financial_Statements[[#This Row],[Column5]]/'Raw Financial Data'!F$6) -> 0.07271542 | F26: =(Financial_Statements[[#This Row],[Column6]]/'Raw Financial Data'!G$6) -> 0.0095400341 | G26: =AVERAGE(D26,E26,F26) -> 0.079788242
A27: o/w attributable to the Group | B27: =(Financial_Statements[[#This Row],[Column2]]/'Raw Financial Data'!C$6) -> 0.17999433 | C27: =(Financial_Statements[[#This Row],[Column3]]/'Raw Financial Data'!D$6) -> 0.17758341 | D27: =(Financial_Statements[[#This Row],[Column4]]/'Raw Financial Data'!E$6) -> 0.15245835 | E27: =(Financial_Statements[[#This Row],[Column5]]/'Raw Financial Data'!F$6) -> 0.06714472 | F27: =(Financial_Statements[[#This Row],[Column6]]/'Raw Financial Data'!G$6) -> 0.0049063032 | G27: =AVERAGE(D27,E27,F27) -> 0.074836456
A28: o/w attributable to minority interests | B28: =(Financial_Statements[[#This Row],[Column2]]/'Raw Financial Data'!C$6) -> 0.0045338623 | C28: =(Financial_Statements[[#This Row],[Column3]]/'Raw Financial Data'!D$6) -> 0.005110314 | D28: =(Financial_Statements[[#This Row],[Column4]]/'Raw Financial Data'!E$6) -> 0.0046509251 | E28: =(Financial_Statements[[#This Row],[Column5]]/'Raw Financial Data'!F$6) -> 0.0055707005 | F28: =(Financial_Statements[[#This Row],[Column6]]/'Raw Financial Data'!G$6) -> 0.0046337308 | G28: =AVERAGE(D28,E28,F28) -> 0.0049517855
A30: (% of Revenue) | B30: 2021 | C30: 2022 | D30: 2023 | E30: 2024 | F30: 2025 | G30: AVG.
A31: Net income attributable to the Group (€m) | B31: =(Financial_Statements[[#This Row],[Column2]]/'Raw Financial Data'!C$6) -> 0.17999433 | C31: =(Financial_Statements[[#This Row],[Column3]]/'Raw Financial Data'!D$6) -> 0.17758341 | D31: =(Financial_Statements[[#This Row],[Column4]]/'Raw Financial Data'!E$6) -> 0.15245835 | E31: =(Financial_Statements[[#This Row],[Column5]]/'Raw Financial Data'!F$6) -> 0.06714472 | F31: =(Financial_Statements[[#This Row],[Column6]]/'Raw Financial Data'!G$6) -> 0.0049063032 | G31: =AVERAGE(D31,E31,F31) -> 0.074836456
A32: Basic earnings per share | B32: =(Financial_Statements[[#This Row],[Column2]]/'Raw Financial Data'!C$6) -> 0.0014446019 | C32: =(Financial_Statements[[#This Row],[Column3]]/'Raw Financial Data'!D$6) -> 0.0014416982 | D32: =(Financial_Statements[[#This Row],[Column4]]/'Raw Financial Data'!E$6) -> 0.001246039 | E32: =(Financial_Statements[[#This Row],[Column5]]/'Raw Financial Data'!F$6) -> 0.00054758801 | F32: =(Financial_Statements[[#This Row],[Column6]]/'Raw Financial Data'!G$6) -> 4.0204429e-05 | G32: =AVERAGE(D32,E32,F32) -> 0.00061127716
A33: Diluted earnings per share | B33: =(Financial_Statements[[#This Row],[Column2]]/'Raw Financial Data'!C$6) -> 0.0014446019 | C33: =(Financial_Statements[[#This Row],[Column3]]/'Raw Financial Data'!D$6) -> 0.0014402241 | D33: =(Financial_Statements[[#This Row],[Column4]]/'Raw Financial Data'!E$6) -> 0.001245528 | E33: =(Financial_Statements[[#This Row],[Column5]]/'Raw Financial Data'!F$6) -> 0.00054758801 | F33: =(Financial_Statements[[#This Row],[Column6]]/'Raw Financial Data'!G$6) -> 4.0204429e-05 | G33: =AVERAGE(D33,E33,F33) -> 0.0006111068
A34: Net income from continuing operations attributable to the Group (€m) | B34: =(Financial_Statements[[#This Row],[Column2]]/'Raw Financial Data'!C$6) -> 0.17937093 | C34: =(Financial_Statements[[#This Row],[Column3]]/'Raw Financial Data'!D$6) -> 0.17753427 | D34: =(Financial_Statements[[#This Row],[Column4]]/'Raw Financial Data'!E$6) -> 0.15245835 | E34: =(Financial_Statements[[#This Row],[Column5]]/'Raw Financial Data'!F$6) -> 0.06074434 | F34: =(Financial_Statements[[#This Row],[Column6]]/'Raw Financial Data'!G$6) -> -0.0019761499 | G34: =AVERAGE(D34,E34,F34) -> 0.070408846
A35: Basic EPS from continuing operations | B35: =(Financial_Statements[[#This Row],[Column2]]/'Raw Financial Data'!C$6) -> 0.0014395013 | C35: =(Financial_Statements[[#This Row],[Column3]]/'Raw Financial Data'!D$6) -> 0.0014412068 | D35: =(Financial_Statements[[#This Row],[Column4]]/'Raw Financial Data'!E$6) -> 0.001246039 | E35: =(Financial_Statements[[#This Row],[Column5]]/'Raw Financial Data'!F$6) -> 0.00049543677 | F35: =(Financial_Statements[[#This Row],[Column6]]/'Raw Financial Data'!G$6) -> -1.5672913e-05 | G35: =AVERAGE(D35,E35,F35) -> 0.00057526763
A36: Diluted EPS from continuing operations | B36: =(Financial_Statements[[#This Row],[Column2]]/'Raw Financial Data'!C$6) -> 0.0014395013 | C36: =(Financial_Statements[[#This Row],[Column3]]/'Raw Financial Data'!D$6) -> 0.0014397327 | D36: =(Financial_Statements[[#This Row],[Column4]]/'Raw Financial Data'!E$6) -> 0.001245528 | E36: =(Financial_Statements[[#This Row],[Column5]]/'Raw Financial Data'!F$6) -> 0.00049543677 | F36: =(Financial_Statements[[#This Row],[Column6]]/'Raw Financial Data'!G$6) -> -1.5672913e-05 | G36: =AVERAGE(D36,E36,F36) -> 0.00057509727
A37: Net income from continuing operations (excluding non recurring items) attributable to the Group (€m) | B37: =(Financial_Statements[[#This Row],[Column2]]/'Raw Financial Data'!C$6) -> 0.19047889 | C37: =(Financial_Statements[[#This Row],[Column3]]/'Raw Financial Data'!D$6) -> 0.18411872 | D37: =(Financial_Statements[[#This Row],[Column4]]/'Raw Financial Data'!E$6) -> 0.15644485 | E37: =(Financial_Statements[[#This Row],[Column5]]/'Raw Financial Data'!F$6) -> 0.071470902 | F37: =(Financial_Statements[[#This Row],[Column6]]/'Raw Financial Data'!G$6) -> 0.036252129 | G37: =AVERAGE(D37,E37,F37) -> 0.088055962
A38: Basic EPS excluding non recurring items | B38: =(Financial_Statements[[#This Row],[Column2]]/'Raw Financial Data'!C$6) -> 0.0015290451 | C38: =(Financial_Statements[[#This Row],[Column3]]/'Raw Financial Data'!D$6) -> 0.0014947668 | D38: =(Financial_Statements[[#This Row],[Column4]]/'Raw Financial Data'!E$6) -> 0.0012787489 | E38: =(Financial_Statements[[#This Row],[Column5]]/'Raw Financial Data'!F$6) -> 0.00058314567 | F38: =(Financial_Statements[[#This Row],[Column6]]/'Raw Financial Data'!G$6) -> 0.00029574106 | G38: =AVERAGE(D38,E38,F38) -> 0.00071921186
A39: Diluted EPS excluding non recurring items | B39: =(Financial_Statements[[#This Row],[Column2]]/'Raw Financial Data'!C$6) -> 0.0015290451 | C39: =(Financial_Statements[[#This Row],[Column3]]/'Raw Financial Data'!D$6) -> 0.0014932927 | D39: =(Financial_Statements[[#This Row],[Column4]]/'Raw Financial Data'!E$6) -> 0.0012782378 | E39: =(Financial_Statements[[#This Row],[Column5]]/'Raw Financial Data'!F$6) -> 0.00058314567 | F39: =(Financial_Statements[[#This Row],[Column6]]/'Raw Financial Data'!G$6) -> 0.00029574106 | G39: =AVERAGE(D39,E39,F39) -> 0.00071904149
A40: Net income from discontinued operations attributable to the Group (€m) | B40: =(Financial_Statements[[#This Row],[Column2]]/'Raw Financial Data'!C$6) -> 0.00062340606 | C40: =(Financial_Statements[[#This Row],[Column3]]/'Raw Financial Data'!D$6) -> 4.9137635e-05 | D40: 0 | E40: =(Financial_Statements[[#This Row],[Column5]]/'Raw Financial Data'!F$6) -> 0.0064003793 | F40: =(Financial_Statements[[#This Row],[Column6]]/'Raw Financial Data'!G$6) -> 0.0068824532 | G40: =AVERAGE(D40,E40,F40) -> 0.0044276108
A41: Basic EPS from discontinued operations | B41: =(Financial_Statements[[#This Row],[Column2]]/'Raw Financial Data'!C$6) -> 5.1005951e-06 | C41: =(Financial_Statements[[#This Row],[Column3]]/'Raw Financial Data'!D$6) -> 4.9137635e-07 | D41: 0 | E41: =(Financial_Statements[[#This Row],[Column5]]/'Raw Financial Data'!F$6) -> 5.2151239e-05 | F41: =(Financial_Statements[[#This Row],[Column6]]/'Raw Financial Data'!G$6) -> 5.5877342e-05 | G41: =AVERAGE(D41,E41,F41) -> 3.6009527e-05
A42: Diluted EPS from discontinued operations | B42: =(Financial_Statements[[#This Row],[Column2]]/'Raw Financial Data'!C$6) -> 5.1005951e-06 | C42: =(Financial_Statements[[#This Row],[Column3]]/'Raw Financial Data'!D$6) -> 4.9137635e-07 | D42: 0 | E42: =(Financial_Statements[[#This Row],[Column5]]/'Raw Financial Data'!F$6) -> 5.2151239e-05 | F42: =(Financial_Statements[[#This Row],[Column6]]/'Raw Financial Data'!G$6) -> 5.5877342e-05 | G42: =AVERAGE(D42,E42,F42) -> 3.6009527e-05
A45: Common Sized Consolidated Balance Sheet (Dec, 31st)
A47: Assets
...

Sheet Brand Contribution Analysis
A1: Revenue Share by Brand
A2: (% of Group Revenue) | B2: 2021 | C2: 2022 | D2: 2023 | E2: 2024 | F2: 2025
A3: Gucci share | B3: ='Raw Financial Data'!C148/'Raw Financial Data'!$C$6 -> 0.55148767 | C3: ='Raw Financial Data'!D148/'Raw Financial Data'!$D$6 -> 0.51530637 | D3: ='Raw Financial Data'!E148/'Raw Financial Data'!$E$6 -> 0.50459982 | E3: ='Raw Financial Data'!F148/'Raw Financial Data'!$F$6 -> 0.4533602 | F3: ='Raw Financial Data'!G148/'Raw Financial Data'!$G$6 -> 0.40831346
A4: Yves Saint Laurent share | B4: ='Raw Financial Data'!C149/'Raw Financial Data'!$C$6 -> 0.14287334 | C4: ='Raw Financial Data'!D149/'Raw Financial Data'!$D$6 -> 0.16215419 | D4: ='Raw Financial Data'!E149/'Raw Financial Data'!$E$6 -> 0.16247572 | E4: ='Raw Financial Data'!F149/'Raw Financial Data'!$F$6 -> 0.17073604 | F4: ='Raw Financial Data'!G149/'Raw Financial Data'!$G$6 -> 0.18010221
A5: Bottega Veneta share | B5: ='Raw Financial Data'!C150/'Raw Financial Data'!$C$6 -> 0.085179938 | C5: ='Raw Financial Data'!D150/'Raw Financial Data'!$D$6 -> 0.085499484 | D5: ='Raw Financial Data'!E150/'Raw Financial Data'!$E$6 -> 0.084074415 | E5: ='Raw Financial Data'!F150/'Raw Financial Data'!$F$6 -> 0.10151713 | F5: ='Raw Financial Data'!G150/'Raw Financial Data'!$G$6 -> 0.11625213
A6: Other houses share | B6: ='Raw Financial Data'!C151/'Raw Financial Data'!$C$6 -> 0.18617172 | C6: ='Raw Financial Data'!D151/'Raw Financial Data'!$D$6 -> 0.1903592 | D6: ='Raw Financial Data'!E151/'Raw Financial Data'!$E$6 -> 0.17959726 | E6: ='Raw Financial Data'!F151/'Raw Financial Data'!$F$6 -> 0.19088539 | F6: ='Raw Financial Data'!G151/'Raw Financial Data'!$G$6 -> 0.19761499
A7: Kering Eyewear & Corporate share | B7: ='Raw Financial Data'!C152/'Raw Financial Data'!$C$6 -> 0.041541513 | C7: ='Raw Financial Data'!D152/'Raw Financial Data'!$D$6 -> 0.055967766 | D7: ='Raw Financial Data'!E152/'Raw Financial Data'!$E$6 -> 0.080139017 | E7: ='Raw Financial Data'!F152/'Raw Financial Data'!$F$6 -> 0.095887164 | F7: ='Raw Financial Data'!G152/'Raw Financial Data'!$G$6 -> 0.1111414
A10: Operating Income Share by Brand
A11: (% of Group Operating Income) | B11: 2021 | C11: 2022 | D11: 2023 | E11: 2024 | F11: 2025
A12: Gucci operating share | B12: ='Raw Financial Data'!C159/'Raw Financial Data'!C$165 -> 0.74048236 | C12: ='Raw Financial Data'!D159/'Raw Financial Data'!D$165 -> 0.6677402 | D12: ='Raw Financial Data'!E159/'Raw Financial Data'!E$165 -> 0.68773704 | E12: ='Raw Financial Data'!F159/'Raw Financial Data'!F$165 -> 0.65778689 | F12: ='Raw Financial Data'!G159/'Raw Financial Data'!G$165 -> 0.59227468
A13: Yves Saint Laurent operating share | B13: ='Raw Financial Data'!C160/'Raw Financial Data'!C$165 -> 0.14251545 | C13: ='Raw Financial Data'!D160/'Raw Financial Data'!D$165 -> 0.18232242 | D13: ='Raw Financial Data'!E160/'Raw Financial Data'!E$165 -> 0.20417193 | E13: ='Raw Financial Data'!F160/'Raw Financial Data'!F$165 -> 0.24303279 | F13: ='Raw Financial Data'!G160/'Raw Financial Data'!G$165 -> 0.3243409
A14: Bottega Veneta operating share | B14: ='Raw Financial Data'!C161/'Raw Financial Data'!C$165 -> 0.057006179 | C14: ='Raw Financial Data'!D161/'Raw Financial Data'!D$165 -> 0.065485776 | D14: ='Raw Financial Data'!E161/'Raw Financial Data'!E$165 -> 0.06573957 | E14: ='Raw Financial Data'!F161/'Raw Financial Data'!F$165 -> 0.1045082 | F14: ='Raw Financial Data'!G161/'Raw Financial Data'!G$165 -> 0.16370325
A15: Other houses operating share | B15: ='Raw Financial Data'!C162/'Raw Financial Data'!C$165 -> 0.091488938 | C15: ='Raw Financial Data'!D162/'Raw Financial Data'!D$165 -> 0.099838969 | D15: ='Raw Financial Data'!E162/'Raw Financial Data'!E$165 -> 0.044669195 | E15: ='Raw Financial Data'!F162/'Raw Financial Data'!F$165 -> -0.0036885246 | F15: ='Raw Financial Data'!G162/'Raw Financial Data'!G$165 -> -0.068669528
A16: Kering Eyewear & Corporate share | B16: ='Raw Financial Data'!C163/'Raw Financial Data'!C$165 -> -0.032688858 | C16: ='Raw Financial Data'!D163/'Raw Financial Data'!D$165 -> -0.015745214 | D16: ='Raw Financial Data'!E163/'Raw Financial Data'!E$165 -> -0.0014749263 | E16: ='Raw Financial Data'!F163/'Raw Financial Data'!F$165 -> -0.00081967213 | F16: ='Raw Financial Data'!G163/'Raw Financial Data'!G$165 -> -0.010423053
A19: Operating Income Decline Attribution
A20: € millions | B20: 2021 | C20: 2025 | D20: Change | E20: % of total
A21: Gucci operating income | B21: ='Raw Financial Data'!C159 -> 3715 | C21: ='Raw Financial Data'!G159 -> 966 | D21: =Operating_Income_Decline_Attribution[[#This Row],[Column3]]-Operating_Income_Decline_Attribution[[#This Row],[Column2]] -> -2749 | E21: =Operating_Income_Decline_Attribution[[#This Row],[Column4]]/D23 -> 0.73306667
A22: Non-Gucci | B22: =B23-B21 -> 1082 | C22: =C23-C21 -> 81 | D22: =Operating_Income_Decline_Attribution[[#This Row],[Column3]]-Operating_Income_Decline_Attribution[[#This Row],[Column2]] -> -1001 | E22: =Operating_Income_Decline_Attribution[[#This Row],[Column4]]/D23 -> 0.26693333
A23: Kering operating income | B23: ='Raw Financial Data'!C13 -> 4797 | C23: ='Raw Financial Data'!G13 -> 1047 | D23: =Operating_Income_Decline_Attribution[[#This Row],[Column3]]-Operating_Income_Decline_Attribution[[#This Row],[Column2]] -> -3750
A26: Operating Margin by Brand
A27: (Operating Margin %) | B27: 2021 | C27: 2022 | D27: 2023 | E27: 2024 | F27: 2025
A28: Gucci margin | B28: ='Raw Financial Data'!C159/'Raw Financial Data'!C148 -> 0.3817696 | C28: ='Raw Financial Data'!D159/'Raw Financial Data'!D148 -> 0.35586917 | D28: ='Raw Financial Data'!E159/'Raw Financial Data'!E148 -> 0.3305986 | E28: ='Raw Financial Data'!F159/'Raw Financial Data'!F148 -> 0.20980392 | F28: ='Raw Financial Data'!G159/'Raw Financial Data'!G148 -> 0.16121495
A29: Yves Saint Laurent margin | B29: ='Raw Financial Data'!C160/'Raw Financial Data'!C149 -> 0.28361761 | C29: ='Raw Financial Data'!D160/'Raw Financial Data'!D149 -> 0.30878788 | D29: ='Raw Financial Data'!E160/'Raw Financial Data'!E149 -> 0.30481283 | E29: ='Raw Financial Data'!F160/'Raw Financial Data'!F149 -> 0.20583131 | F29: ='Raw Financial Data'!G160/'Raw Financial Data'!G149 -> 0.20015134
A30: Bottega Veneta margin | B30: ='Raw Financial Data'!C161/'Raw Financial Data'!C150 -> 0.19028609 | C30: ='Raw Financial Data'!D161/'Raw Financial Data'!D150 -> 0.21034483 | D30: ='Raw Financial Data'!E161/'Raw Financial Data'!E150 -> 0.18966565 | E30: ='Raw Financial Data'!F161/'Raw Financial Data'!F150 -> 0.14886165 | F30: ='Raw Financial Data'!G161/'Raw Financial Data'!G150 -> 0.15650645
A31: Other houses margin | B31: ='Raw Financial Data'!C162/'Raw Financial Data'!C151 -> 0.13972603 | C31: ='Raw Financial Data'!D162/'Raw Financial Data'!D151 -> 0.14403717 | D31: ='Raw Financial Data'!E162/'Raw Financial Data'!E151 -> 0.060330108 | E31: ='Raw Financial Data'!F162/'Raw Financial Data'!F151 -> -0.0027941633 | F31: ='Raw Financial Data'!G162/'Raw Financial Data'!G151 -> -0.03862069
A32: Kering operating margin | B32: ='Raw Financial Data'!C13/'Raw Financial Data'!C6 -> 0.27186172 | C32: ='Raw Financial Data'!D13/'Raw Financial Data'!D6 -> 0.26509754 | D32: ='Raw Financial Data'!E13/'Raw Financial Data'!E6 -> 0.2372994 | E32: ='Raw Financial Data'!F13/'Raw Financial Data'!F6 -> 0.13025957 | F32: ='Raw Financial Data'!G13/'Raw Financial Data'!G6 -> 0.071345826

Sheet Financial Trend Analysis
A1: Revenue Trend Comparison | H1: Operating Income Trend Comparison
B2: 2021 | C2: 2022 | D2: 2023 | E2: 2024 | F2: 2025 | I2: 2021 | J2: 2022 | K2: 2023 | L2: 2024 | M2: 2025
A3: Kering revenue | B3: ='Raw Financial Data'!C6 -> 17645 | C3: ='Raw Financial Data'!D6 -> 20351 | D3: ='Raw Financial Data'!E6 -> 19566 | E3: ='Raw Financial Data'!F6 -> 16874 | F3: ='Raw Financial Data'!G6 -> 14675 | H3: Kering operating income | I3: ='Raw Financial Data'!C13 -> 4797 | J3: ='Raw Financial Data'!D13 -> 5395 | K3: ='Raw Financial Data'!E13 -> 4643 | L3: ='Raw Financial Data'!F13 -> 2198 | M3: ='Raw Financial Data'!G13 -> 1047
A4: Gucci revenue | B4: ='Raw Financial Data'!C148 -> 9731 | C4: ='Raw Financial Data'!D148 -> 10487 | D4: ='Raw Financial Data'!E148 -> 9873 | E4: ='Raw Financial Data'!F148 -> 7650 | F4: ='Raw Financial Data'!G148 -> 5992 | H4: Gucci operating income | I4: ='Raw Financial Data'!C159 -> 3715 | J4: ='Raw Financial Data'!D159 -> 3732 | K4: ='Raw Financial Data'!E159 -> 3264 | L4: ='Raw Financial Data'!F159 -> 1605 | M4: ='Raw Financial Data'!G159 -> 966
A5: Gucci revenue share of Kering | B5: ='Brand Contribution Analysis'!B3 -> 0.55148767 | C5: ='Brand Contribution Analysis'!C3 -> 0.51530637 | D5: ='Brand Contribution Analysis'!D3 -> 0.50459982 | E5: ='Brand Contribution Analysis'!E3 -> 0.4533602 | F5: ='Brand Contribution Analysis'!F3 -> 0.40831346 | H5: Gucci operating income share | I5: ='Brand Contribution Analysis'!B12 -> 0.74048236 | J5: ='Brand Contribution Analysis'!C12 -> 0.6677402 | K5: ='Brand Contribution Analysis'!D12 -> 0.68773704 | L5: ='Brand Contribution Analysis'!E12 -> 0.65778689 | M5: ='Brand Contribution Analysis'!F12 -> 0.59227468
A20: Operating Margin Trend Comparison | H20: Cost Structure (% of Revenue)
B21: 2021 | C21: 2022 | D21: 2023 | E21: 2024 | F21: 2025 | I21: 2021 | J21: 2022 | K21: 2023 | L21: 2024 | M21: 2025
A22: Kering operating margin | B22: =I3/B3 -> 0.27186172 | C22: =J3/C3 -> 0.26509754 | D22: =K3/D3 -> 0.2372994 | E22: =L3/E3 -> 0.13025957 | F22: =M3/F3 -> 0.071345826 | H22: COGS as % of revenue | I22: =ABS('Raw Financial Data'!C7/'Raw Financial Data'!C6) -> 0.2593936 | J22: =ABS('Raw Financial Data'!D7/'Raw Financial Data'!D6) -> 0.25320623 | K22: =ABS('Raw Financial Data'!E7/'Raw Financial Data'!E6) -> 0.23709496 | L22: =ABS('Raw Financial Data'!F7/'Raw Financial Data'!F6) -> 0.26549721 | M22: =ABS('Raw Financial Data'!G7/'Raw Financial Data'!G6) -> 0.27359455
A23: Gucci operating margin | B23: =I4/B4 -> 0.3817696 | C23: =J4/C4 -> 0.35586917 | D23: =K4/D4 -> 0.3305986 | E23: =L4/E4 -> 0.20980392 | F23: =M4/F4 -> 0.16121495 | H23: Operating expenses as % of revenue | I23: =ABS(('Raw Financial Data'!C9+'Raw Financial Data'!C10)/'Raw Financial Data'!C6) -> 0.45627657 | J23: =ABS(('Raw Financial Data'!D9+'Raw Financial Data'!D10)/'Raw Financial Data'!D6) -> 0.47216353 | K23: =ABS(('Raw Financial Data'!E9+'Raw Financial Data'!E10)/'Raw Financial Data'!E6) -> 0.52034141 | L23: =ABS(('Raw Financial Data'!F9+'Raw Financial Data'!F10)/'Raw Financial Data'!F6) -> 0.58990162 | M23: =ABS(('Raw Financial Data'!G9+'Raw Financial Data'!G10)/'Raw Financial Data'!G6) -> 0.61526405

Sheet Returns & Efficiency Analysis
A2: Returns & Efficiency Analysis | B2: 2021 | C2: 2022 | D2: 2023 | E2: 2024 | F2: 2025
A4: Return on Equity
A5: ROE | B5: ='Raw Financial Data'!C31/AVERAGE(11821,'Raw Financial Data'!C75) -> 0.25238398 | C5: ='Raw Financial Data'!D31/AVERAGE('Raw Financial Data'!C75:D75) -> 0.2643262 | D5: ='Raw Financial Data'!E31/AVERAGE('Raw Financial Data'!D75:E75) -> 0.20424512 | E5: ='Raw Financial Data'!F31/AVERAGE('Raw Financial Data'!E75:F75) -> 0.075242396 | F5: ='Raw Financial Data'!G31/AVERAGE('Raw Financial Data'!F75:G75) -> 0.0048632219
A7: DuPont Decomposition
A8: Net margin | B8: ='Raw Financial Data'!C31/'Raw Financial Data'!C6 -> 0.17999433 | C8: ='Raw Financial Data'!D31/'Raw Financial Data'!D6 -> 0.17758341 | D8: ='Raw Financial Data'!E31/'Raw Financial Data'!E6 -> 0.15245835 | E8: ='Raw Financial Data'!F31/'Raw Financial Data'!F6 -> 0.06714472 | F8: ='Raw Financial Data'!G31/'Raw Financial Data'!G6 -> 0.0049063032
A9: Asset turnover | B9: ='Raw Financial Data'!C6/AVERAGE('Raw Financial Data'!B70:C70) -> 0.5973924 | C9: ='Raw Financial Data'!D6/AVERAGE('Raw Financial Data'!C70:D70) -> 0.62609792 | D9: ='Raw Financial Data'!E6/AVERAGE('Raw Financial Data'!D70:E70) -> 0.51962607 | E9: ='Raw Financial Data'!F6/AVERAGE('Raw Financial Data'!E70:F70) -> 0.39838041 | F9: ='Raw Financial Data'!G6/AVERAGE('Raw Financial Data'!F70:G70) -> 0.34722222
A10: Equity multiplier | B10: =AVERAGE('Raw Financial Data'!B70:C70)/AVERAGE('Raw Financial Data'!B75:C75) -> 2.3471724 | C10: =AVERAGE('Raw Financial Data'!C70:D70)/AVERAGE('Raw Financial Data'!C75:D75) -> 2.3773633 | D10: =AVERAGE('Raw Financial Data'!D70:E70)/AVERAGE('Raw Financial Data'!D75:E75) -> 2.5781582 | E10: =AVERAGE('Raw Financial Data'!E70:F70)/AVERAGE('Raw Financial Data'!E75:F75) -> 2.8128902 | F10: =AVERAGE('Raw Financial Data'!F70:G70)/AVERAGE('Raw Financial Data'!F75:G75) -> 2.8547112
A11: ROE check | B11: =B8*B9*B10 -> 0.25238498 | C11: =C8*C9*C10 -> 0.2643262 | D11: =D8*D9*D10 -> 0.20424512 | E11: =E8*E9*E10 -> 0.075242396 | F11: =F8*F9*F10 -> 0.0048632219
A13: Profitability Drivers
A14: Gross margin | B14: =ABS('Raw Financial Data'!C8/'Raw Financial Data'!C6) -> 0.7406064 | C14: =ABS('Raw Financial Data'!D8/'Raw Financial Data'!D6) -> 0.74679377 | D14: =ABS('Raw Financial Data'!E8/'Raw Financial Data'!E6) -> 0.76290504 | E14: =ABS('Raw Financial Data'!F8/'Raw Financial Data'!F6) -> 0.73450279 | F14: =ABS('Raw Financial Data'!G8/'Raw Financial Data'!G6) -> 0.72640545
A15: Operating expenses as % of sales | B15: =ABS('Raw Financial Data'!C9+'Raw Financial Data'!C10)/'Raw Financial Data'!C6 -> 0.45627657 | C15: =ABS('Raw Financial Data'!D9+'Raw Financial Data'!D10)/'Raw Financial Data'!D6 -> 0.47216353 | D15: =ABS('Raw Financial Data'!E9+'Raw Financial Data'!E10)/'Raw Financial Data'!E6 -> 0.52034141 | E15: =ABS('Raw Financial Data'!F9+'Raw Financial Data'!F10)/'Raw Financial Data'!F6 -> 0.58990162 | F15: =ABS('Raw Financial Data'!G9+'Raw Financial Data'!G10)/'Raw Financial Data'!G6 -> 0.61526405
A16: Operating margin | B16: ='Raw Financial Data'!C13/'Raw Financial Data'!C6 -> 0.27186172 | C16: ='Raw Financial Data'!D13/'Raw Financial Data'!D6 -> 0.26509754 | D16: ='Raw Financial Data'!E13/'Raw Financial Data'!E6 -> 0.2372994 | E16: ='Raw Financial Data'!F13/'Raw Financial Data'!F6 -> 0.13025957 | F16: ='Raw Financial Data'!G13/'Raw Financial Data'!G6 -> 0.071345826
A17: Interest expense as percent of sales | B17: =ABS('Raw Financial Data'!C14/'Raw Financial Data'!C6) -> 0.015471805 | C17: =ABS('Raw Financial Data'!D14/'Raw Financial Data'!D6) -> 0.012775785 | D17: =ABS('Raw Financial Data'!E14/'Raw Financial Data'!E6) -> 0.020954717 | E17: =ABS('Raw Financial Data'!F14/'Raw Financial Data'!F6) -> 0.036387341 | F17: =ABS('Raw Financial Data'!G14/'Raw Financial Data'!G6) -> 0.040477002
A18: Effective tax rate | B18: =ABS('Raw Financial Data'!C16/'Raw Financial Data'!C15) -> 0.28293546 | C18: =ABS('Raw Financial Data'!D16/'Raw Financial Data'!D15) -> 0.27653359 | D18: =ABS('Raw Financial Data'!E16/'Raw Financial Data'!E15) -> 0.27474604 | E18: =ABS('Raw Financial Data'!F16/'Raw Financial Data'!F15) -> 0.28724747 | F18: =ABS('Raw Financial Data'!G16/'Raw Financial Data'!G15) -> 0.78145695
A20: Return on Invested Capital
A21: NOPAT | B21: ='Raw Financial Data'!C13*(1-'Returns & Efficiency Analysis'!B18) -> 3439.7586 | C21: ='Raw Financial Data'!D13*(1-'Returns & Efficiency Analysis'!C18) -> 3903.1013 | D21: ='Raw Financial Data'!E13*(1-'Returns & Efficiency Analysis'!D18) -> 3367.3541 | E21: ='Raw Financial Data'!F13*(1-'Returns & Efficiency Analysis'!E18) -> 1566.6301 | F21: ='Raw Financial Data'!G13*(1-'Returns & Efficiency Analysis'!F18) -> 228.81457
A22: Avg. Invested Capital | B22: =AVERAGE(('Raw Financial Data'!B77+'Raw Financial Data'!B80+'Raw Financial Data'!B90-'Raw Financial Data'!B66),('Raw Financial Data'!C77+'Raw Financial Data'!C80+'Raw Financial Data'!C90-'Raw Financial Data'!C66)) -> 14044.35 | C22: =AVERAGE(('Raw Financial Data'!C77+'Raw Financial Data'!C80+'Raw Financial Data'!C90-'Raw Financial Data'!C66),('Raw Financial Data'!D77+'Raw Financial Data'!D80+'Raw Financial Data'!D90-'Raw Financial Data'!D66)) -> 15497 | D22: =AVERAGE(('Raw Financial Data'!D77+'Raw Financial Data'!D80+'Raw Financial Data'!D90-'Raw Financial Data'!D66),('Raw Financial Data'!E77+'Raw Financial Data'!E80+'Raw Financial Data'!E90-'Raw Financial Data'!E66)) -> 20801.5 | E22: =AVERAGE(('Raw Financial Data'!E77+'Raw Financial Data'!E80+'Raw Financial Data'!E90-'Raw Financial Data'!E66),('Raw Financial Data'!F77+'Raw Financial Data'!F80+'Raw Financial Data'!F90-'Raw Financial Data'!F66)) -> 25380.5 | F22: =AVERAGE(('Raw Financial Data'!F77+'Raw Financial Data'!F80+'Raw Financial Data'!F90-'Raw Financial Data'!F66),('Raw Financial Data'!G77+'Raw Financial Data'!G80+'Raw Financial Data'!G90-'Raw Financial Data'!G66)) -> 24900.5
A23: ROIC | B23: =B21/B22 -> 0.24492117 | C23: =C21/C22 -> 0.25186173 | D23: =D21/D22 -> 0.16188035 | E23: =E21/E22 -> 0.061725736 | F23: =F21/F22 -> 0.0091891556
A25: Working Capital Efficiency
A26: Inventory turnover | B26: =ABS('Raw Financial Data'!C7/AVERAGE('Raw Financial Data'!B61,'Raw Financial Data'!C61)) -> 1.4730067 | C26: =ABS('Raw Financial Data'!D7/AVERAGE('Raw Financial Data'!C61,'Raw Financial Data'!D61)) -> 1.3155476 | D26: =ABS('Raw Financial Data'!E7/AVERAGE('Raw Financial Data'!D61,'Raw Financial Data'!E61)) -> 1.0291736 | E26: =ABS('Raw Financial Data'!F7/AVERAGE('Raw Financial Data'!E61,'Raw Financial Data'!F61)) -> 1.0489347 | F26: =ABS('Raw Financial Data'!G7/AVERAGE('Raw Financial Data'!F61,'Raw Financial Data'!G61)) -> 1.0470726
A27: Days inventory outstanding | B27: =365/B26 -> 247.7925 | C27: =365/C26 -> 277.451 | D27: =365/D26 -> 354.65348 | E27: =365/E26 -> 347.9721 | F27: =365/F26 -> 348.59091
A28: Receivable days | B28: =(AVERAGE('Raw Financial Data'!B62,'Raw Financial Data'!C62)/'Raw Financial Data'!C6)*365 -> 19.521139 | C28: =(AVERAGE('Raw Financial Data'!C62,'Raw Financial Data'!D62)/'Raw Financial Data'!D6)*365 -> 19.343153 | D28: =(AVERAGE('Raw Financial Data'!D62,'Raw Financial Data'!E62)/'Raw Financial Data'!E6)*365 -> 21.74218 | E28: =(AVERAGE('Raw Financial Data'!E62,'Raw Financial Data'!F62)/'Raw Financial Data'!F6)*365 -> 23.296492 | F28: =(AVERAGE('Raw Financial Data'!F62,'Raw Financial Data'!G62)/'Raw Financial Data'!G6)*365 -> 22.720784
A29: Payable days | B29: =ABS(AVERAGE('Raw Financial Data'!B93,'Raw Financial Data'!C93)/'Raw Financial Data'!C7)*365 -> 128.85449 | C29: =ABS(AVERAGE('Raw Financial Data'!C93,'Raw Financial Data'!D93)/'Raw Financial Data'!D7)*365 -> 141.84213 | D29: =ABS(AVERAGE('Raw Financial Data'!D93,'Raw Financial Data'!E93)/'Raw Financial Data'!E7)*365 -> 175.57609 | E29: =ABS(AVERAGE('Raw Financial Data'!E93,'Raw Financial Data'!F93)/'Raw Financial Data'!F7)*365 -> 175.08594 | F29: =ABS(AVERAGE('Raw Financial Data'!F93,'Raw Financial Data'!G93)/'Raw Financial Data'!G7)*365 -> 181.63636
A30: Cash conversion cycle | B30: =B27+B28-B29 -> 138.45914 | C30: =C27+C28-C29 -> 154.95202 | D30: =D27+D28-D29 -> 200.81957 | E30: =E27+E28-E29 -> 196.18265 | F30: =F27+F28-F29 -> 189.67533

Sheet Forecast & Scenario Analysis
A1: SALES FORCAST
A3: Forecast Assumption
A4: Forecast Driver | B4: Factual Evidence Considered | H4: Forecast Assumption Used
A5: Luxury market outlook | B5: Market expected to grow 3% to 5% in 2026 after ending 2025 flat. Long term growth of 4% to 6% annually through 2035 (D'Arpizio et al., 2025, Bain and Altagamma). | H5: Kering is still recovering in 2026, so it will grow slower than the overall market. By 2027 and 2028, as the turnaround takes hold, growth rates are expected to catch up.
A6: Shrinking customer base | B6: Active luxury customers fell from 400 million in 2022 to 330 million in 2025, returning to 2013 levels. New client acquisition dropped 5% in 2025 (D'Arpizio et al., 2025, Bain and Altagamma). | H6: Kering cannot rely on attracting new customers to drive growth right now. Every brand needs to win back its existing high spending clients first, which naturally slows down the recovery.
A7: Management guidance | B7: CEO De Meo: "We have seen signs of rebound for nearly all our brands." Return to growth and margin improvement confirmed as 2026 objectives. Full strategy to be presented April 16, 2026 (Abnett, 2026, Business of Fashion). | H7: Management has publicly committed to returning to growth in 2026. No specific number has been given, so this confirms the direction but sets no hard target.
A8: Store rationalisation | B8: Kering plans to close 100 stores in 2026, mostly Gucci locations in Asia. 75 net closures already completed in 2025 (Abnett, 2026, Business of Fashion; Kering, 2025, Annual Results). | H8: Closures will suppress 2026 reported revenue even if consumer demand improves. Comparable growth will outpace reported growth.
A9: Gucci decline trajectory | B9: Quarterly comparable decline improved from minus 25% in Q1 to minus 10% in Q4 2025. Wholesale cut intentionally by 34%. Full year minus 19% comparable (Kering, 2025, Annual Results). | H9: Gucci hit its low point in 2025. A small further decline is expected in 2026 while the transition completes, followed by a meaningful recovery in 2027 once the new creative direction is fully in market.
A10: Gucci creative reset | B10: Demna's full commercial collection launches July 2026. A limited drop in February 2026 was described by the CEO as a signal of "speed and dynamism" (Kering, 2026, press release). | H10: Demna's full collection only reaches stores in July 2026, giving it roughly half a year to generate sales. The full financial impact will only show up in 2027.
A11: Yves Saint Laurent | B11: Minus 6% comparable in 2025. North America returned to positive in Q3 and Q4. Operating margin held at 20.0%. New CEO Charbit in seat since January 2025 (Kering, 2025, Annual Results). | H11: YSL has no brand or creative problems. The slowdown was purely driven by weak consumer confidence. As conditions improve, low single digit growth from 2026 is a realistic expectation.
A12: Bottega Veneta | B12: Plus 3% comparable in 2025. North America plus 18%. EBITDA margin expanded to 29.0%. Louise Trotter's debut collections drove strong leather goods and online performance (Kering, 2025, Annual Results). | H12: Bottega is the strongest performing brand in the portfolio right now. New creative direction, strong sales and expanding margins. Steady growth assumed with no major risks in sight.
A13: Other Houses | B13: Recurring operating loss of €112 million in 2025. Balenciaga and McQueen in active restructuring. Jewellery houses including Boucheron and Qeelin growing. Net 27 store closures in 2025 (Kering, 2025, Annual Results). | H13: Balenciaga and McQueen are still cutting costs and closing stores while losing money. Jewellery brands are growing but not enough to cover the losses. A return to positive growth is only realistic from 2027.
A14: Kering Eyewear | B14: Plus 3% comparable in 2025 driven by Cartier, Bottega Veneta and Saint Laurent frames. Tariff headwinds and Maui Jim investment flagged as near term constraints (Kering, 2025, Annual Results). | H14: Eyewear is a strong long term growth business for Kering. Near term growth is capped at 4% to 5% annually due to tariff pressures and ongoing investment in Maui Jim.
A15: China and Asia risk | B15: Asia Pacific fell 15% comparable in 2025. China luxury spending contracted 3% to 5% in 2025 as consumers shifted toward local brands. Asia represents 29% of Kering revenue (D'Arpizio et al., 2025, Bain and Altagamma; Kering, 2025, Annual Results). | H15: Asia fell 15% in 2025 as Chinese consumers moved away from Western luxury toward local brands. This is not a temporary slowdown, so no meaningful recovery is assumed before 2027.
A17: Forecasting by brand
B18: 2021 | C18: 2022 | D18: 2023 | E18: 2024 | F18: 2025 | G18: 2026 Growth Assumption | H18: 2026F | I18: 2027 Growth Assumption | J18: 2027F | K18: 2028 Growth Assumption | L18: 2028F
A19: Gucci | B19: 9731 | C19: 10487 | D19: 9873 | E19: 7650 | F19: 5992 | G19: -0.03 | H19: =Forcasting_Revenue[[#This Row],[Column6]]*(1+Forcasting_Revenue[[#This Row],[Column7]]) -> 5812.24 | I19: 0.03 | J19: =Forcasting_Revenue[[#This Row],[Column8]]*(1+Forcasting_Revenue[[#This Row],[Column9]]) -> 5986.6072 | K19: 0.05 | L19: =Forcasting_Revenue[[#This Row],[Column10]]*(1+Forcasting_Revenue[[#This Row],[Column11]]) -> 6285.9376
A20: Yves Saint Laurent | B20: 2521 | C20: 3300 | D20: 3179 | E20: 2881 | F20: 2643 | G20: 0.01 | H20: =Forcasting_Revenue[[#This Row],[Column6]]*(1+Forcasting_Revenue[[#This Row],[Column7]]) -> 2669.43 | I20: 0.025 | J20: =Forcasting_Revenue[[#This Row],[Column8]]*(1+Forcasting_Revenue[[#This Row],[Column9]]) -> 2736.1657 | K20: 0.035 | L20: =Forcasting_Revenue[[#This Row],[Column10]]*(1+Forcasting_Revenue[[#This Row],[Column11]]) -> 2831.9316
A21: Bottega Veneta | B21: 1503 | C21: 1740 | D21: 1645 | E21: 1713 | F21: 1706 | G21: 0.03 | H21: =Forcasting_Revenue[[#This Row],[Column6]]*(1+Forcasting_Revenue[[#This Row],[Column7]]) -> 1757.18 | I21: 0.04 | J21: =Forcasting_Revenue[[#This Row],[Column8]]*(1+Forcasting_Revenue[[#This Row],[Column9]]) -> 1827.4672 | K21: 0.05 | L21: =Forcasting_Revenue[[#This Row],[Column10]]*(1+Forcasting_Revenue[[#This Row],[Column11]]) -> 1918.8406
A22: Other Houses | B22: 3285 | C22: 3874 | D22: 3514 | E22: 3221 | F22: 2900 | G22: -0.02 | H22: =Forcasting_Revenue[[#This Row],[Column6]]*(1+Forcasting_Revenue[[#This Row],[Column7]]) -> 2842 | I22: 0.01 | J22: =Forcasting_Revenue[[#This Row],[Column8]]*(1+Forcasting_Revenue[[#This Row],[Column9]]) -> 2870.42 | K22: 0.02 | L22: =Forcasting_Revenue[[#This Row],[Column10]]*(1+Forcasting_Revenue[[#This Row],[Column11]]) -> 2927.8284
A23: Kering Eyewear | B23: 733 | C23: 1139 | D23: 1568 | E23: 1618 | F23: 1631 | G23: 0.03 | H23: =Forcasting_Revenue[[#This Row],[Column6]]*(1+Forcasting_Revenue[[#This Row],[Column7]]) -> 1679.93 | I23: 0.04 | J23: =Forcasting_Revenue[[#This Row],[Column8]]*(1+Forcasting_Revenue[[#This Row],[Column9]]) -> 1747.1272 | K23: 0.04 | L23: =Forcasting_Revenue[[#This Row],[Column10]]*(1+Forcasting_Revenue[[#This Row],[Column11]]) -> 1817.0123
A24: Total Kering Revenue | B24: 17645 | C24: 20351 | D24: 19566 | E24: 16874 | F24: 14675 | G24: =(Forcasting_Revenue[[#This Row],[Column8]]-Forcasting_Revenue[[#This Row],[Column6]])/Forcasting_Revenue[[#This Row],[Column6]] -> 0.0058453152 | H24: =SUM(H19:H23) -> 14760.78 | I24: =(Forcasting_Revenue[[#This Row],[Column10]]-Forcasting_Revenue[[#This Row],[Column8]])/Forcasting_Revenue[[#This Row],[Column8]] -> 0.027573567 | J24: =SUM(J19:J23) -> 15167.787 | K24: =(Forcasting_Revenue[[#This Row],[Column12]]-Forcasting_Revenue[[#This Row],[Column10]])/Forcasting_Revenue[[#This Row],[Column10]] -> 0.040464901 | L24: =SUM(L19:L23) -> 15781.55
B41: 2021 | C41: 2022 | D41: 2023 | E41: 2024 | F41: 2025 | G41: 2026F | H41: 2027F | I41: 2028F
A42: Kering revenue growth | B42: 0.346926 | C42: 0.15335789 | D42: -0.038573043 | E42: -0.13758561 | F42: -0.13031883 | G42: =G24 -> 0.0058453152 | H42: =I24 -> 0.027573567 | I42: =K24 -> 0.040464901
A44: FINANCIAL FORECAST
A46: Income Statement Forecast
A47: (in € millions) | B47: 2021 | C47: 2022 | D47: 2023 | E47: 2024 | F47: 2025 | G47: 2026F | H47: 2027F | I47: 2028F
A48: Revenue | B48: ='Raw Financial Data'!C6 -> 17645 | C48: ='Raw Financial Data'!D6 -> 20351 | D48: ='Raw Financial Data'!E6 -> 19566 | E48: ='Raw Financial Data'!F6 -> 16874 | F48: ='Raw Financial Data'!G6 -> 14675 | G48: =H24 -> 14760.78 | H48: =J24 -> 15167.787 | I48: =L24 -> 15781.55
A49: Cost of Sales | B49: =ABS('Raw Financial Data'!C7) -> 4577 | C49: =ABS('Raw Financial Data'!D7) -> 5153 | D49: =ABS('Raw Financial Data'!E7) -> 4639 | E49: =ABS('Raw Financial Data'!F7) -> 4480 | F49: =ABS('Raw Financial Data'!G7) -> 4015 | G49: =ABS('Common Size Financial Statement'!$G$7*G48) -> 3819.0405 | H49: =ABS('Common Size Financial Statement'!$G$7*H48) -> 3924.3451 | I49: =ABS('Common Size Financial Statement'!$G$7*I48) -> 4083.1433
A50: Gross Profit | B50: =B48-B49 -> 13068 | C50: =C48-C49 -> 15198 | D50: =D48-D49 -> 14927 | E50: =E48-E49 -> 12394 | F50: =F48-F49 -> 10660 | G50: =G48-G49 -> 10941.74 | H50: =H48-H49 -> 11243.442 | I50: =I48-I49 -> 11698.407
A51: Operating Expenses | B51: =ABS('Raw Financial Data'!B9+'Raw Financial Data'!B10) -> 6374.4 | C51: =ABS('Raw Financial Data'!C9+'Raw Financial Data'!C10) -> 8051 | D51: =ABS('Raw Financial Data'!D9+'Raw Financial Data'!D10) -> 9609 | E51: =ABS('Raw Financial Data'!E9+'Raw Financial Data'!E10) -> 10181 | F51: =ABS('Raw Financial Data'!F9+'Raw Financial Data'!F10) -> 9954 | G51: =ABS(('Common Size Financial Statement'!$G$9*'Forecast & Scenario Analysis'!G48)+('Common Size Financial Statement'!$G$10*'Forecast & Scenario Analysis'!G48)) -> 8489.9435 | H51: =ABS(('Common Size Financial Statement'!$G$9*'Forecast & Scenario Analysis'!H48)+('Common Size Financial Statement'!$G$10*'Forecast & Scenario Analysis'!H48)) -> 8724.0415 | I51: =ABS(('Common Size Financial Statement'!$G$9*'Forecast & Scenario Analysis'!I48)+('Common Size Financial Statement'!$G$10*'Forecast & Scenario Analysis'!I48)) -> 9077.059
A52: Operating Income | B52: ='Raw Financial Data'!C13 -> 4797 | C52: ='Raw Financial Data'!D13 -> 5395 | D52: ='Raw Financial Data'!E13 -> 4643 | E52: ='Raw Financial Data'!F13 -> 2198 | F52: ='Raw Financial Data'!G13 -> 1047 | G52: ='Common Size Financial Statement'!$G$13*G48 -> 2159.5257 | H52: ='Common Size Financial Statement'!$G$13*H48 -> 2219.0715 | I52: ='Common Size Financial Statement'!$G$13*I48 -> 2308.866
A53: Net Income | B53: ='Raw Financial Data'!C31 -> 3176 | C53: ='Raw Financial Data'!D31 -> 3614 | D53: ='Raw Financial Data'!E31 -> 2983 | E53: ='Raw Financial Data'!F31 -> 1133 | F53: ='Raw Financial Data'!G31 -> 72 | G53: ='Common Size Financial Statement'!$G$31*'Forecast & Scenario Analysis'!G48 -> 1104.6445 | H53: ='Common Size Financial Statement'!$G$31*'Forecast & Scenario Analysis'!H48 -> 1135.1035 | I53: ='Common Size Financial Statement'!$G$31*'Forecast & Scenario Analysis'!I48 -> 1181.0353
A56: Returns Forecast
A57: Returns calculation | B57: 2021 | C57: 2022 | D57: 2023 | E57: 2024 | F57: 2025 | G57: 2026F | H57: 2027F | I57: 2028F
A58: Income Tax Expense | B58: =ABS('Raw Financial Data'!C16) -> 1280 | C58: =ABS('Raw Financial Data'!D16) -> 1420 | D58: =ABS('Raw Financial Data'!E16) -> 1163 | E58: =ABS('Raw Financial Data'!F16) -> 455 | F58: =ABS('Raw Financial Data'!G16) -> 354 | G58: =ABS('Common Size Financial Statement'!$G$16*'Forecast & Scenario Analysis'!G48) -> 543.82189 | H58: =ABS('Common Size Financial Statement'!$G$16*'Forecast & Scenario Analysis'!H48) -> 558.817 | I58: =ABS('Common Size Financial Statement'!$G$16*'Forecast & Scenario Analysis'!I48) -> 581.42947
A59: Income Before Tax | B59: ='Raw Financial Data'!C15 -> 4524 | C59: ='Raw Financial Data'!D15 -> 5135 | D59: ='Raw Financial Data'!E15 -> 4233 | E59: ='Raw Financial Data'!F15 -> 1584 | F59: ='Raw Financial Data'!G15 -> 453 | G59: ='Common Size Financial Statement'!$G$15*'Forecast & Scenario Analysis'!G48 -> 1678.2305 | H59: ='Common Size Financial Statement'!$G$15*'Forecast & Scenario Analysis'!H48 -> 1724.5053 | I59: ='Common Size Financial Statement'!$G$15*'Forecast & Scenario Analysis'!I48 -> 1794.2872
A60: Tax rate | B60: =B58/B59 -> 0.28293546 | C60: =C58/C59 -> 0.27653359 | D60: =D58/D59 -> 0.27474604 | E60: =E58/E59 -> 0.28724747 | F60: =F58/F59 -> 0.78145695 | G60: =G58/G59 -> 0.32404481 | H60: =H58/H59 -> 0.32404481 | I60: =I58/I59 -> 0.32404481
A61: NOPAT | B61: =B52*(1-B60) -> 3439.7586 | C61: =C52*(1-C60) -> 3903.1013 | D61: =D52*(1-D60) -> 3367.3541 | E61: =E52*(1-E60) -> 1566.6301 | F61: =F52*(1-F60) -> 228.81457 | G61: =G52*(1-G60) -> 1459.7426 | H61: =H52*(1-H60) -> 1499.9929 | I61: =I52*(1-I60) -> 1560.69
A62: TATR | B62: ='Raw Financial Data'!C6/AVERAGE('Raw Financial Data'!B70,'Raw Financial Data'!C70) -> 0.5973924 | C62: ='Raw Financial Data'!D6/AVERAGE('Raw Financial Data'!C70,'Raw Financial Data'!D70) -> 0.62609792 | D62: ='Raw Financial Data'!E6/AVERAGE('Raw Financial Data'!D70,'Raw Financial Data'!E70) -> 0.51962607 | E62: ='Raw Financial Data'!F6/AVERAGE('Raw Financial Data'!E70,'Raw Financial Data'!F70) -> 0.39838041 | F62: ='Raw Financial Data'!G6/AVERAGE('Raw Financial Data'!F70,'Raw Financial Data'!G70) -> 0.34722222 | G62: =G48/AVERAGE(F63,G63) -> 0.34722222 | H62: =H48/AVERAGE(G63,H63) -> 0.34722222 | I62: =I48/AVERAGE(H63,I63) -> 0.34722222
...

Sheet Core Findings
A2: Kering S.A. - Financial Analysis Conclusion
A3: Research question: To what extent does Gucci's performance influence Kering's overall financial performance and profitability?
A15: 1. Decline in Group Financial Performance
A39: 2. High Dependence on Gucci
J59: Gucci Drove 73% of the €3,7500M Profit Collapse of Kering
A63: 3. Gucci Driving Group Margin Decline
A86: 4. Deterioration in Profitability and Returns
K89: Decline in Returns Driven by Margin Compression
M91: 2021 | N91: 2025
K92: Net margin | M92: 0.17999433 | N92: 0.0049063032
K93: Asset turnover | M93: 0.5973924 | N93: 0.34722222
K94: Equity multiplier | M94: 2.3471724 | N94: 2.8547112
A106: 5. Outlook Driven by Gucci’s Recovery
P113: Gucci risk

Sheet Strategic Conclusions
A3: ✓ | B3: FINAL INTERPRETATION | L3: WHAT SHOULD MANAGEMENT DO?
